File: data/ti-6al-4v/Data/SHPB/Lee1998/Backup/Lee1998-Fig3-573K-1400.csv
# Lee1998 Figure 3
# Temperature: 573 K
# Strain rate: 1400 s^-1
# -----------
# Chemistry (weight %)
# Ti, Bal.
#  Y, 0.0
#  N, 0.008
#  C, 0.014
#  H, 0.0057
# Fe, 0.2
#  O, 0.15
# Al, 6.1
#  V, 4.0
# ----------
# True strain, True stress (MPa)
0,935.87
0.01,1025.97
0.02,1056.95
0.03,1079.48
0.04,1096.12
0.05,1111.12
0.06,1123.94
0.07,1135.83
0.08,1146.63
0.09,1155.39
0.1,1165.67
0.11,1172.15
0.12,1180.05
0.13,1187.37
0.14,1194.2
0.15,1200.86
0.16,1207.59
0.17,1211.27
0.18,1219.27